[2024-12-30 14:56:06,012] {taskinstance.py:1159} INFO - Dependencies all met for <TaskInstance: dag_with_taskflow_api_v3.greet manual__2024-12-30T14:56:04.676259+00:00 [queued]>
[2024-12-30 14:56:06,019] {taskinstance.py:1159} INFO - Dependencies all met for <TaskInstance: dag_with_taskflow_api_v3.greet manual__2024-12-30T14:56:04.676259+00:00 [queued]>
[2024-12-30 14:56:06,019] {taskinstance.py:1356} INFO - 
--------------------------------------------------------------------------------
[2024-12-30 14:56:06,019] {taskinstance.py:1357} INFO - Starting attempt 1 of 6
[2024-12-30 14:56:06,019] {taskinstance.py:1358} INFO - 
--------------------------------------------------------------------------------
[2024-12-30 14:56:06,028] {taskinstance.py:1377} INFO - Executing <Task(_PythonDecoratedOperator): greet> on 2024-12-30 14:56:04.676259+00:00
[2024-12-30 14:56:06,031] {standard_task_runner.py:52} INFO - Started process 691 to run task
[2024-12-30 14:56:06,033] {standard_task_runner.py:79} INFO - Running: ['***', 'tasks', 'run', 'dag_with_taskflow_api_v3', 'greet', 'manual__2024-12-30T14:56:04.676259+00:00', '--job-id', '14', '--raw', '--subdir', 'DAGS_FOLDER/dag_with_taskflow_api.py', '--cfg-path', '/tmp/tmpqbouki11', '--error-file', '/tmp/tmpx8gav1c8']
[2024-12-30 14:56:06,034] {standard_task_runner.py:80} INFO - Job 14: Subtask greet
[2024-12-30 14:56:06,066] {task_command.py:370} INFO - Running <TaskInstance: dag_with_taskflow_api_v3.greet manual__2024-12-30T14:56:04.676259+00:00 [running]> on host 0c4a021d66c8
[2024-12-30 14:56:06,104] {taskinstance.py:1889} ERROR - Task failed with exception
Traceback (most recent call last):
  File "/home/airflow/.local/lib/python3.7/site-packages/airflow/models/taskinstance.py", line 1451, in _run_raw_task
    self._execute_task_with_callbacks(context, test_mode)
  File "/home/airflow/.local/lib/python3.7/site-packages/airflow/models/taskinstance.py", line 1555, in _execute_task_with_callbacks
    task_orig = self.render_templates(context=context)
  File "/home/airflow/.local/lib/python3.7/site-packages/airflow/models/taskinstance.py", line 2212, in render_templates
    rendered_task = self.task.render_template_fields(context)
  File "/home/airflow/.local/lib/python3.7/site-packages/airflow/models/baseoperator.py", line 1185, in render_template_fields
    self._do_render_template_fields(self, self.template_fields, context, jinja_env, set())
  File "/home/airflow/.local/lib/python3.7/site-packages/airflow/utils/session.py", line 71, in wrapper
    return func(*args, session=session, **kwargs)
  File "/home/airflow/.local/lib/python3.7/site-packages/airflow/models/abstractoperator.py", line 348, in _do_render_template_fields
    seen_oids,
  File "/home/airflow/.local/lib/python3.7/site-packages/airflow/models/abstractoperator.py", line 398, in render_template
    return tuple(self.render_template(element, context, jinja_env) for element in value)
  File "/home/airflow/.local/lib/python3.7/site-packages/airflow/models/abstractoperator.py", line 398, in <genexpr>
    return tuple(self.render_template(element, context, jinja_env) for element in value)
  File "/home/airflow/.local/lib/python3.7/site-packages/airflow/models/abstractoperator.py", line 394, in render_template
    return value.resolve(context)
  File "/home/airflow/.local/lib/python3.7/site-packages/airflow/utils/session.py", line 71, in wrapper
    return func(*args, session=session, **kwargs)
  File "/home/airflow/.local/lib/python3.7/site-packages/airflow/models/xcom_arg.py", line 153, in resolve
    f'XComArg result from {self.operator.task_id} at {context["ti"].dag_id} '
airflow.exceptions.AirflowException: XComArg result from get_name at dag_with_taskflow_api_v3 with key="first_name" is not found!
[2024-12-30 14:56:06,107] {taskinstance.py:1400} INFO - Marking task as UP_FOR_RETRY. dag_id=dag_with_taskflow_api_v3, task_id=greet, execution_date=20241230T145604, start_date=20241230T145606, end_date=20241230T145606
[2024-12-30 14:56:06,114] {standard_task_runner.py:97} ERROR - Failed to execute job 14 for task greet (XComArg result from get_name at dag_with_taskflow_api_v3 with key="first_name" is not found!; 691)
[2024-12-30 14:56:06,125] {local_task_job.py:156} INFO - Task exited with return code 1
[2024-12-30 14:56:06,147] {local_task_job.py:273} INFO - 0 downstream tasks scheduled from follow-on schedule check
