[2024-12-30 12:23:39,030] {taskinstance.py:1159} INFO - Dependencies all met for <TaskInstance: first_py_dag_V2.greet manual__2024-12-30T12:23:37.274476+00:00 [queued]>
[2024-12-30 12:23:39,036] {taskinstance.py:1159} INFO - Dependencies all met for <TaskInstance: first_py_dag_V2.greet manual__2024-12-30T12:23:37.274476+00:00 [queued]>
[2024-12-30 12:23:39,037] {taskinstance.py:1356} INFO - 
--------------------------------------------------------------------------------
[2024-12-30 12:23:39,037] {taskinstance.py:1357} INFO - Starting attempt 1 of 6
[2024-12-30 12:23:39,037] {taskinstance.py:1358} INFO - 
--------------------------------------------------------------------------------
[2024-12-30 12:23:39,046] {taskinstance.py:1377} INFO - Executing <Task(PythonOperator): greet> on 2024-12-30 12:23:37.274476+00:00
[2024-12-30 12:23:39,050] {standard_task_runner.py:52} INFO - Started process 13985 to run task
[2024-12-30 12:23:39,052] {standard_task_runner.py:79} INFO - Running: ['***', 'tasks', 'run', 'first_py_dag_V2', 'greet', 'manual__2024-12-30T12:23:37.274476+00:00', '--job-id', '27', '--raw', '--subdir', 'DAGS_FOLDER/first_dag.py', '--cfg-path', '/tmp/tmpv0th79zq', '--error-file', '/tmp/tmp95_426a1']
[2024-12-30 12:23:39,053] {standard_task_runner.py:80} INFO - Job 27: Subtask greet
[2024-12-30 12:23:39,084] {task_command.py:370} INFO - Running <TaskInstance: first_py_dag_V2.greet manual__2024-12-30T12:23:37.274476+00:00 [running]> on host 0766066e7c2f
[2024-12-30 12:23:39,133] {taskinstance.py:1571} INFO - Exporting the following env vars:
AIRFLOW_CTX_DAG_OWNER=swetansu
AIRFLOW_CTX_DAG_ID=first_py_dag_V2
AIRFLOW_CTX_TASK_ID=greet
AIRFLOW_CTX_EXECUTION_DATE=2024-12-30T12:23:37.274476+00:00
AIRFLOW_CTX_TRY_NUMBER=1
AIRFLOW_CTX_DAG_RUN_ID=manual__2024-12-30T12:23:37.274476+00:00
[2024-12-30 12:23:39,133] {taskinstance.py:1889} ERROR - Task failed with exception
Traceback (most recent call last):
  File "/home/airflow/.local/lib/python3.7/site-packages/airflow/operators/python.py", line 171, in execute
    return_value = self.execute_callable()
  File "/home/airflow/.local/lib/python3.7/site-packages/airflow/operators/python.py", line 189, in execute_callable
    return self.python_callable(*self.op_args, **self.op_kwargs)
  File "/opt/airflow/dags/first_dag.py", line 13, in greet
    name = ti.xcom_pull(task_id="get_name")
  File "/home/airflow/.local/lib/python3.7/site-packages/airflow/utils/session.py", line 71, in wrapper
    return func(*args, session=session, **kwargs)
TypeError: xcom_pull() got an unexpected keyword argument 'task_id'
[2024-12-30 12:23:39,139] {taskinstance.py:1400} INFO - Marking task as UP_FOR_RETRY. dag_id=first_py_dag_V2, task_id=greet, execution_date=20241230T122337, start_date=20241230T122339, end_date=20241230T122339
[2024-12-30 12:23:39,146] {standard_task_runner.py:97} ERROR - Failed to execute job 27 for task greet (xcom_pull() got an unexpected keyword argument 'task_id'; 13985)
[2024-12-30 12:23:39,184] {local_task_job.py:156} INFO - Task exited with return code 1
[2024-12-30 12:23:39,217] {local_task_job.py:273} INFO - 0 downstream tasks scheduled from follow-on schedule check
