[2024-12-30 12:32:57,944] {taskinstance.py:1159} INFO - Dependencies all met for <TaskInstance: first_py_dag_V4.get_name manual__2024-12-30T12:32:56.963982+00:00 [queued]>
[2024-12-30 12:32:57,959] {taskinstance.py:1159} INFO - Dependencies all met for <TaskInstance: first_py_dag_V4.get_name manual__2024-12-30T12:32:56.963982+00:00 [queued]>
[2024-12-30 12:32:57,959] {taskinstance.py:1356} INFO - 
--------------------------------------------------------------------------------
[2024-12-30 12:32:57,959] {taskinstance.py:1357} INFO - Starting attempt 1 of 6
[2024-12-30 12:32:57,959] {taskinstance.py:1358} INFO - 
--------------------------------------------------------------------------------
[2024-12-30 12:32:57,976] {taskinstance.py:1377} INFO - Executing <Task(PythonOperator): get_name> on 2024-12-30 12:32:56.963982+00:00
[2024-12-30 12:32:57,984] {standard_task_runner.py:52} INFO - Started process 14563 to run task
[2024-12-30 12:32:57,987] {standard_task_runner.py:79} INFO - Running: ['***', 'tasks', 'run', 'first_py_dag_V4', 'get_name', 'manual__2024-12-30T12:32:56.963982+00:00', '--job-id', '33', '--raw', '--subdir', 'DAGS_FOLDER/first_dag.py', '--cfg-path', '/tmp/tmpzw3ftvx0', '--error-file', '/tmp/tmp7ra5r3ew']
[2024-12-30 12:32:57,988] {standard_task_runner.py:80} INFO - Job 33: Subtask get_name
[2024-12-30 12:32:58,037] {task_command.py:370} INFO - Running <TaskInstance: first_py_dag_V4.get_name manual__2024-12-30T12:32:56.963982+00:00 [running]> on host 0766066e7c2f
[2024-12-30 12:32:58,099] {taskinstance.py:1571} INFO - Exporting the following env vars:
AIRFLOW_CTX_DAG_OWNER=swetansu
AIRFLOW_CTX_DAG_ID=first_py_dag_V4
AIRFLOW_CTX_TASK_ID=get_name
AIRFLOW_CTX_EXECUTION_DATE=2024-12-30T12:32:56.963982+00:00
AIRFLOW_CTX_TRY_NUMBER=1
AIRFLOW_CTX_DAG_RUN_ID=manual__2024-12-30T12:32:56.963982+00:00
[2024-12-30 12:32:58,100] {taskinstance.py:1889} ERROR - Task failed with exception
Traceback (most recent call last):
  File "/home/airflow/.local/lib/python3.7/site-packages/airflow/operators/python.py", line 171, in execute
    return_value = self.execute_callable()
  File "/home/airflow/.local/lib/python3.7/site-packages/airflow/operators/python.py", line 189, in execute_callable
    return self.python_callable(*self.op_args, **self.op_kwargs)
  File "/opt/airflow/dags/first_dag.py", line 23, in get_name
    ti.xcom.push(key="first_name", Value="swetansu")
AttributeError: 'TaskInstance' object has no attribute 'xcom'
[2024-12-30 12:32:58,107] {taskinstance.py:1400} INFO - Marking task as UP_FOR_RETRY. dag_id=first_py_dag_V4, task_id=get_name, execution_date=20241230T123256, start_date=20241230T123257, end_date=20241230T123258
[2024-12-30 12:32:58,117] {standard_task_runner.py:97} ERROR - Failed to execute job 33 for task get_name ('TaskInstance' object has no attribute 'xcom'; 14563)
[2024-12-30 12:32:58,160] {local_task_job.py:156} INFO - Task exited with return code 1
[2024-12-30 12:32:58,205] {local_task_job.py:273} INFO - 0 downstream tasks scheduled from follow-on schedule check
